[2020-06-12 21:06:24,209][INFO] Start watching sub-server status ...
[2020-06-12 21:06:24,337][INFO] Connect to central server 192.168.191.249 success
[2020-06-12 21:06:24,338][INFO] Start sub-server http://192.168.191.249:8080
[2020-06-12 21:12:42,551][INFO] Appium iOS starts connecting.
[2020-06-12 21:12:42,552][INFO] Automated testing starts success.
[2020-06-12 21:12:42,574][INFO] Appium iOS starts connecting.
[2020-06-12 21:12:42,574][INFO] Automated testing starts success.
[2020-06-12 21:12:42,941][ERROR] Traceback (most recent call last):
  File "/Users/bindo1111/Documents/trash/qauto_sub_server/platforms/identifier.py", line 46, in connect
    cls.DRIVER = iOSAppium(cls.session)
  File "/Users/bindo1111/Documents/trash/qauto_sub_server/core/refactor/ios.py", line 34, in __init__
    super().__init__(session, platform="ios")
  File "/Users/bindo1111/Documents/trash/qauto_sub_server/core/refactor/appium_refactor.py", line 45, in __init__
    self.init_driver = webdriver.Remote("http://localhost:4723/wd/hub", session)
  File "/Library/Frameworks/Python.framework/Versions/3.7/lib/python3.7/site-packages/appium/webdriver/webdriver.py", line 151, in __init__
    proxy
  File "/Library/Frameworks/Python.framework/Versions/3.7/lib/python3.7/site-packages/selenium/webdriver/remote/webdriver.py", line 157, in __init__
    self.start_session(capabilities, browser_profile)
  File "/Library/Frameworks/Python.framework/Versions/3.7/lib/python3.7/site-packages/appium/webdriver/webdriver.py", line 227, in start_session
    response = self.execute(RemoteCommand.NEW_SESSION, parameters)
  File "/Library/Frameworks/Python.framework/Versions/3.7/lib/python3.7/site-packages/selenium/webdriver/remote/webdriver.py", line 321, in execute
    self.error_handler.check_response(response)
  File "/Library/Frameworks/Python.framework/Versions/3.7/lib/python3.7/site-packages/selenium/webdriver/remote/errorhandler.py", line 242, in check_response
    raise exception_class(message, screen, stacktrace)
selenium.common.exceptions.WebDriverException: Message: An unknown server-side error occurred while processing the command. Original error: Unknown device or simulator UDID: '18b61a7bcd83c7d47a8e5a3d4c0202a6b2807c6f'


[2020-06-12 21:12:42,942][ERROR] Traceback (most recent call last):
  File "/Users/bindo1111/Documents/trash/qauto_sub_server/platforms/identifier.py", line 46, in connect
    cls.DRIVER = iOSAppium(cls.session)
  File "/Users/bindo1111/Documents/trash/qauto_sub_server/core/refactor/ios.py", line 34, in __init__
    super().__init__(session, platform="ios")
  File "/Users/bindo1111/Documents/trash/qauto_sub_server/core/refactor/appium_refactor.py", line 45, in __init__
    self.init_driver = webdriver.Remote("http://localhost:4723/wd/hub", session)
  File "/Library/Frameworks/Python.framework/Versions/3.7/lib/python3.7/site-packages/appium/webdriver/webdriver.py", line 151, in __init__
    proxy
  File "/Library/Frameworks/Python.framework/Versions/3.7/lib/python3.7/site-packages/selenium/webdriver/remote/webdriver.py", line 157, in __init__
    self.start_session(capabilities, browser_profile)
  File "/Library/Frameworks/Python.framework/Versions/3.7/lib/python3.7/site-packages/appium/webdriver/webdriver.py", line 227, in start_session
    response = self.execute(RemoteCommand.NEW_SESSION, parameters)
  File "/Library/Frameworks/Python.framework/Versions/3.7/lib/python3.7/site-packages/selenium/webdriver/remote/webdriver.py", line 321, in execute
    self.error_handler.check_response(response)
  File "/Library/Frameworks/Python.framework/Versions/3.7/lib/python3.7/site-packages/selenium/webdriver/remote/errorhandler.py", line 242, in check_response
    raise exception_class(message, screen, stacktrace)
selenium.common.exceptions.WebDriverException: Message: An unknown server-side error occurred while processing the command. Original error: Unknown device or simulator UDID: '18b61a7bcd83c7d47a8e5a3d4c0202a6b2807c6f'


[2020-06-12 21:12:42,942][INFO] Appium iOS connects finished.
[2020-06-12 21:12:42,942][INFO] Appium iOS connects finished.
[2020-06-12 21:12:42,973][INFO] ================== Finished in 0.4s. ==================
[2020-06-12 21:12:42,974][INFO] ================== Finished in 0.4s. ==================
[2020-06-12 21:23:41,201][INFO] Appium iOS starts connecting.
[2020-06-12 21:23:41,201][INFO] Automated testing starts success.
[2020-06-12 21:23:41,219][INFO] Appium iOS starts connecting.
[2020-06-12 21:23:41,219][INFO] Automated testing starts success.
[2020-06-12 21:23:41,525][ERROR] Traceback (most recent call last):
  File "/Users/bindo1111/Documents/trash/qauto_sub_server/platforms/identifier.py", line 46, in connect
    cls.DRIVER = iOSAppium(cls.session)
  File "/Users/bindo1111/Documents/trash/qauto_sub_server/core/refactor/ios.py", line 34, in __init__
    super().__init__(session, platform="ios")
  File "/Users/bindo1111/Documents/trash/qauto_sub_server/core/refactor/appium_refactor.py", line 45, in __init__
    self.init_driver = webdriver.Remote("http://localhost:4723/wd/hub", session)
  File "/Library/Frameworks/Python.framework/Versions/3.7/lib/python3.7/site-packages/appium/webdriver/webdriver.py", line 151, in __init__
    proxy
  File "/Library/Frameworks/Python.framework/Versions/3.7/lib/python3.7/site-packages/selenium/webdriver/remote/webdriver.py", line 157, in __init__
    self.start_session(capabilities, browser_profile)
  File "/Library/Frameworks/Python.framework/Versions/3.7/lib/python3.7/site-packages/appium/webdriver/webdriver.py", line 227, in start_session
    response = self.execute(RemoteCommand.NEW_SESSION, parameters)
  File "/Library/Frameworks/Python.framework/Versions/3.7/lib/python3.7/site-packages/selenium/webdriver/remote/webdriver.py", line 321, in execute
    self.error_handler.check_response(response)
  File "/Library/Frameworks/Python.framework/Versions/3.7/lib/python3.7/site-packages/selenium/webdriver/remote/errorhandler.py", line 242, in check_response
    raise exception_class(message, screen, stacktrace)
selenium.common.exceptions.WebDriverException: Message: An unknown server-side error occurred while processing the command. Original error: Unknown device or simulator UDID: '18b61a7bcd83c7d47a8e5a3d4c0202a6b2807c6f'


[2020-06-12 21:23:41,525][INFO] Appium iOS connects finished.
[2020-06-12 21:23:41,528][ERROR] Traceback (most recent call last):
  File "/Users/bindo1111/Documents/trash/qauto_sub_server/platforms/identifier.py", line 46, in connect
    cls.DRIVER = iOSAppium(cls.session)
  File "/Users/bindo1111/Documents/trash/qauto_sub_server/core/refactor/ios.py", line 34, in __init__
    super().__init__(session, platform="ios")
  File "/Users/bindo1111/Documents/trash/qauto_sub_server/core/refactor/appium_refactor.py", line 45, in __init__
    self.init_driver = webdriver.Remote("http://localhost:4723/wd/hub", session)
  File "/Library/Frameworks/Python.framework/Versions/3.7/lib/python3.7/site-packages/appium/webdriver/webdriver.py", line 151, in __init__
    proxy
  File "/Library/Frameworks/Python.framework/Versions/3.7/lib/python3.7/site-packages/selenium/webdriver/remote/webdriver.py", line 157, in __init__
    self.start_session(capabilities, browser_profile)
  File "/Library/Frameworks/Python.framework/Versions/3.7/lib/python3.7/site-packages/appium/webdriver/webdriver.py", line 227, in start_session
    response = self.execute(RemoteCommand.NEW_SESSION, parameters)
  File "/Library/Frameworks/Python.framework/Versions/3.7/lib/python3.7/site-packages/selenium/webdriver/remote/webdriver.py", line 321, in execute
    self.error_handler.check_response(response)
  File "/Library/Frameworks/Python.framework/Versions/3.7/lib/python3.7/site-packages/selenium/webdriver/remote/errorhandler.py", line 242, in check_response
    raise exception_class(message, screen, stacktrace)
selenium.common.exceptions.WebDriverException: Message: An unknown server-side error occurred while processing the command. Original error: Unknown device or simulator UDID: '18b61a7bcd83c7d47a8e5a3d4c0202a6b2807c6f'


[2020-06-12 21:23:41,528][INFO] Appium iOS connects finished.
[2020-06-12 21:23:41,550][INFO] ================== Finished in 0.3s. ==================
[2020-06-12 21:23:41,552][INFO] ================== Finished in 0.4s. ==================
[2020-06-12 21:33:25,685][INFO] Appium iOS starts connecting.
[2020-06-12 21:33:25,685][INFO] Automated testing starts success.
[2020-06-12 21:33:25,702][INFO] Appium iOS starts connecting.
[2020-06-12 21:33:25,703][INFO] Automated testing starts success.
[2020-06-12 21:33:26,327][ERROR] Traceback (most recent call last):
  File "/Users/bindo1111/Documents/trash/qauto_sub_server/platforms/identifier.py", line 46, in connect
    cls.DRIVER = iOSAppium(cls.session)
  File "/Users/bindo1111/Documents/trash/qauto_sub_server/core/refactor/ios.py", line 34, in __init__
    super().__init__(session, platform="ios")
  File "/Users/bindo1111/Documents/trash/qauto_sub_server/core/refactor/appium_refactor.py", line 45, in __init__
    self.init_driver = webdriver.Remote("http://localhost:4723/wd/hub", session)
  File "/Library/Frameworks/Python.framework/Versions/3.7/lib/python3.7/site-packages/appium/webdriver/webdriver.py", line 151, in __init__
    proxy
  File "/Library/Frameworks/Python.framework/Versions/3.7/lib/python3.7/site-packages/selenium/webdriver/remote/webdriver.py", line 157, in __init__
    self.start_session(capabilities, browser_profile)
  File "/Library/Frameworks/Python.framework/Versions/3.7/lib/python3.7/site-packages/appium/webdriver/webdriver.py", line 227, in start_session
    response = self.execute(RemoteCommand.NEW_SESSION, parameters)
  File "/Library/Frameworks/Python.framework/Versions/3.7/lib/python3.7/site-packages/selenium/webdriver/remote/webdriver.py", line 321, in execute
    self.error_handler.check_response(response)
  File "/Library/Frameworks/Python.framework/Versions/3.7/lib/python3.7/site-packages/selenium/webdriver/remote/errorhandler.py", line 242, in check_response
    raise exception_class(message, screen, stacktrace)
selenium.common.exceptions.WebDriverException: Message: An unknown server-side error occurred while processing the command. Original error: Unknown device or simulator UDID: '18b61a7bcd83c7d47a8e5a3d4c0202a6b2807c6f'


[2020-06-12 21:33:26,327][INFO] Appium iOS connects finished.
[2020-06-12 21:33:26,332][ERROR] Traceback (most recent call last):
  File "/Users/bindo1111/Documents/trash/qauto_sub_server/platforms/identifier.py", line 46, in connect
    cls.DRIVER = iOSAppium(cls.session)
  File "/Users/bindo1111/Documents/trash/qauto_sub_server/core/refactor/ios.py", line 34, in __init__
    super().__init__(session, platform="ios")
  File "/Users/bindo1111/Documents/trash/qauto_sub_server/core/refactor/appium_refactor.py", line 45, in __init__
    self.init_driver = webdriver.Remote("http://localhost:4723/wd/hub", session)
  File "/Library/Frameworks/Python.framework/Versions/3.7/lib/python3.7/site-packages/appium/webdriver/webdriver.py", line 151, in __init__
    proxy
  File "/Library/Frameworks/Python.framework/Versions/3.7/lib/python3.7/site-packages/selenium/webdriver/remote/webdriver.py", line 157, in __init__
    self.start_session(capabilities, browser_profile)
  File "/Library/Frameworks/Python.framework/Versions/3.7/lib/python3.7/site-packages/appium/webdriver/webdriver.py", line 227, in start_session
    response = self.execute(RemoteCommand.NEW_SESSION, parameters)
  File "/Library/Frameworks/Python.framework/Versions/3.7/lib/python3.7/site-packages/selenium/webdriver/remote/webdriver.py", line 321, in execute
    self.error_handler.check_response(response)
  File "/Library/Frameworks/Python.framework/Versions/3.7/lib/python3.7/site-packages/selenium/webdriver/remote/errorhandler.py", line 242, in check_response
    raise exception_class(message, screen, stacktrace)
selenium.common.exceptions.WebDriverException: Message: An unknown server-side error occurred while processing the command. Original error: Unknown device or simulator UDID: '18b61a7bcd83c7d47a8e5a3d4c0202a6b2807c6f'


[2020-06-12 21:33:26,333][INFO] Appium iOS connects finished.
[2020-06-12 21:33:26,497][ERROR] Status code is 500

[2020-06-12 21:33:26,497][INFO] ================== Finished in 0.8s. ==================
[2020-06-12 21:33:26,503][ERROR] Status code is 500

[2020-06-12 21:33:26,503][INFO] ================== Finished in 0.8s. ==================
[2020-06-12 21:38:02,740][INFO] Appium iOS starts connecting.
[2020-06-12 21:38:02,740][INFO] Automated testing starts success.
[2020-06-12 21:38:02,757][INFO] Appium iOS starts connecting.
[2020-06-12 21:38:02,757][INFO] Automated testing starts success.
[2020-06-12 21:38:03,035][ERROR] Traceback (most recent call last):
  File "/Users/bindo1111/Documents/trash/qauto_sub_server/platforms/identifier.py", line 46, in connect
    cls.DRIVER = iOSAppium(cls.session)
  File "/Users/bindo1111/Documents/trash/qauto_sub_server/core/refactor/ios.py", line 34, in __init__
    super().__init__(session, platform="ios")
  File "/Users/bindo1111/Documents/trash/qauto_sub_server/core/refactor/appium_refactor.py", line 45, in __init__
    self.init_driver = webdriver.Remote("http://localhost:4723/wd/hub", session)
  File "/Library/Frameworks/Python.framework/Versions/3.7/lib/python3.7/site-packages/appium/webdriver/webdriver.py", line 151, in __init__
    proxy
  File "/Library/Frameworks/Python.framework/Versions/3.7/lib/python3.7/site-packages/selenium/webdriver/remote/webdriver.py", line 157, in __init__
    self.start_session(capabilities, browser_profile)
  File "/Library/Frameworks/Python.framework/Versions/3.7/lib/python3.7/site-packages/appium/webdriver/webdriver.py", line 227, in start_session
    response = self.execute(RemoteCommand.NEW_SESSION, parameters)
  File "/Library/Frameworks/Python.framework/Versions/3.7/lib/python3.7/site-packages/selenium/webdriver/remote/webdriver.py", line 321, in execute
    self.error_handler.check_response(response)
  File "/Library/Frameworks/Python.framework/Versions/3.7/lib/python3.7/site-packages/selenium/webdriver/remote/errorhandler.py", line 242, in check_response
    raise exception_class(message, screen, stacktrace)
selenium.common.exceptions.WebDriverException: Message: An unknown server-side error occurred while processing the command. Original error: Unknown device or simulator UDID: '18b61a7bcd83c7d47a8e5a3d4c0202a6b2807c6f'


[2020-06-12 21:38:03,035][ERROR] Traceback (most recent call last):
  File "/Users/bindo1111/Documents/trash/qauto_sub_server/platforms/identifier.py", line 46, in connect
    cls.DRIVER = iOSAppium(cls.session)
  File "/Users/bindo1111/Documents/trash/qauto_sub_server/core/refactor/ios.py", line 34, in __init__
    super().__init__(session, platform="ios")
  File "/Users/bindo1111/Documents/trash/qauto_sub_server/core/refactor/appium_refactor.py", line 45, in __init__
    self.init_driver = webdriver.Remote("http://localhost:4723/wd/hub", session)
  File "/Library/Frameworks/Python.framework/Versions/3.7/lib/python3.7/site-packages/appium/webdriver/webdriver.py", line 151, in __init__
    proxy
  File "/Library/Frameworks/Python.framework/Versions/3.7/lib/python3.7/site-packages/selenium/webdriver/remote/webdriver.py", line 157, in __init__
    self.start_session(capabilities, browser_profile)
  File "/Library/Frameworks/Python.framework/Versions/3.7/lib/python3.7/site-packages/appium/webdriver/webdriver.py", line 227, in start_session
    response = self.execute(RemoteCommand.NEW_SESSION, parameters)
  File "/Library/Frameworks/Python.framework/Versions/3.7/lib/python3.7/site-packages/selenium/webdriver/remote/webdriver.py", line 321, in execute
    self.error_handler.check_response(response)
  File "/Library/Frameworks/Python.framework/Versions/3.7/lib/python3.7/site-packages/selenium/webdriver/remote/errorhandler.py", line 242, in check_response
    raise exception_class(message, screen, stacktrace)
selenium.common.exceptions.WebDriverException: Message: An unknown server-side error occurred while processing the command. Original error: Unknown device or simulator UDID: '18b61a7bcd83c7d47a8e5a3d4c0202a6b2807c6f'


[2020-06-12 21:38:03,035][INFO] Appium iOS connects finished.
[2020-06-12 21:38:03,036][INFO] Appium iOS connects finished.
[2020-06-12 21:38:03,161][ERROR] Status code is 500

[2020-06-12 21:38:03,162][INFO] ================== Finished in 0.4s. ==================
[2020-06-12 21:38:03,163][ERROR] Status code is 500

[2020-06-12 21:38:03,163][INFO] ================== Finished in 0.4s. ==================
[2020-06-12 21:39:48,408][INFO] Appium iOS starts connecting.
[2020-06-12 21:39:48,408][INFO] Automated testing starts success.
[2020-06-12 21:39:48,432][INFO] Appium iOS starts connecting.
[2020-06-12 21:39:48,432][INFO] Automated testing starts success.
[2020-06-12 21:39:48,711][ERROR] Traceback (most recent call last):
  File "/Users/bindo1111/Documents/trash/qauto_sub_server/platforms/identifier.py", line 46, in connect
    cls.DRIVER = iOSAppium(cls.session)
  File "/Users/bindo1111/Documents/trash/qauto_sub_server/core/refactor/ios.py", line 34, in __init__
    super().__init__(session, platform="ios")
  File "/Users/bindo1111/Documents/trash/qauto_sub_server/core/refactor/appium_refactor.py", line 45, in __init__
    self.init_driver = webdriver.Remote("http://localhost:4723/wd/hub", session)
  File "/Library/Frameworks/Python.framework/Versions/3.7/lib/python3.7/site-packages/appium/webdriver/webdriver.py", line 151, in __init__
    proxy
  File "/Library/Frameworks/Python.framework/Versions/3.7/lib/python3.7/site-packages/selenium/webdriver/remote/webdriver.py", line 157, in __init__
    self.start_session(capabilities, browser_profile)
  File "/Library/Frameworks/Python.framework/Versions/3.7/lib/python3.7/site-packages/appium/webdriver/webdriver.py", line 227, in start_session
    response = self.execute(RemoteCommand.NEW_SESSION, parameters)
  File "/Library/Frameworks/Python.framework/Versions/3.7/lib/python3.7/site-packages/selenium/webdriver/remote/webdriver.py", line 321, in execute
    self.error_handler.check_response(response)
  File "/Library/Frameworks/Python.framework/Versions/3.7/lib/python3.7/site-packages/selenium/webdriver/remote/errorhandler.py", line 242, in check_response
    raise exception_class(message, screen, stacktrace)
selenium.common.exceptions.WebDriverException: Message: An unknown server-side error occurred while processing the command. Original error: Unknown device or simulator UDID: '18b61a7bcd83c7d47a8e5a3d4c0202a6b2807c6f'


[2020-06-12 21:39:48,711][INFO] Appium iOS connects finished.
[2020-06-12 21:39:48,735][ERROR] Traceback (most recent call last):
  File "/Users/bindo1111/Documents/trash/qauto_sub_server/platforms/identifier.py", line 46, in connect
    cls.DRIVER = iOSAppium(cls.session)
  File "/Users/bindo1111/Documents/trash/qauto_sub_server/core/refactor/ios.py", line 34, in __init__
    super().__init__(session, platform="ios")
  File "/Users/bindo1111/Documents/trash/qauto_sub_server/core/refactor/appium_refactor.py", line 45, in __init__
    self.init_driver = webdriver.Remote("http://localhost:4723/wd/hub", session)
  File "/Library/Frameworks/Python.framework/Versions/3.7/lib/python3.7/site-packages/appium/webdriver/webdriver.py", line 151, in __init__
    proxy
  File "/Library/Frameworks/Python.framework/Versions/3.7/lib/python3.7/site-packages/selenium/webdriver/remote/webdriver.py", line 157, in __init__
    self.start_session(capabilities, browser_profile)
  File "/Library/Frameworks/Python.framework/Versions/3.7/lib/python3.7/site-packages/appium/webdriver/webdriver.py", line 227, in start_session
    response = self.execute(RemoteCommand.NEW_SESSION, parameters)
  File "/Library/Frameworks/Python.framework/Versions/3.7/lib/python3.7/site-packages/selenium/webdriver/remote/webdriver.py", line 321, in execute
    self.error_handler.check_response(response)
  File "/Library/Frameworks/Python.framework/Versions/3.7/lib/python3.7/site-packages/selenium/webdriver/remote/errorhandler.py", line 242, in check_response
    raise exception_class(message, screen, stacktrace)
selenium.common.exceptions.WebDriverException: Message: An unknown server-side error occurred while processing the command. Original error: Unknown device or simulator UDID: '18b61a7bcd83c7d47a8e5a3d4c0202a6b2807c6f'


[2020-06-12 21:39:48,736][INFO] Appium iOS connects finished.
[2020-06-12 21:39:48,741][INFO] ================== Finished in 0.3s. ==================
[2020-06-12 21:39:48,767][INFO] ================== Finished in 0.4s. ==================
[2020-06-12 21:44:16,968][INFO] Appium iOS starts connecting.
[2020-06-12 21:44:16,968][INFO] Automated testing starts success.
[2020-06-12 21:44:16,987][INFO] Appium iOS starts connecting.
[2020-06-12 21:44:16,987][INFO] Automated testing starts success.
[2020-06-12 21:44:17,296][ERROR] Traceback (most recent call last):
  File "/Users/bindo1111/Documents/trash/qauto_sub_server/platforms/identifier.py", line 46, in connect
    cls.DRIVER = iOSAppium(cls.session)
  File "/Users/bindo1111/Documents/trash/qauto_sub_server/core/refactor/ios.py", line 34, in __init__
    super().__init__(session, platform="ios")
  File "/Users/bindo1111/Documents/trash/qauto_sub_server/core/refactor/appium_refactor.py", line 45, in __init__
    self.init_driver = webdriver.Remote("http://localhost:4723/wd/hub", session)
  File "/Library/Frameworks/Python.framework/Versions/3.7/lib/python3.7/site-packages/appium/webdriver/webdriver.py", line 151, in __init__
    proxy
  File "/Library/Frameworks/Python.framework/Versions/3.7/lib/python3.7/site-packages/selenium/webdriver/remote/webdriver.py", line 157, in __init__
    self.start_session(capabilities, browser_profile)
  File "/Library/Frameworks/Python.framework/Versions/3.7/lib/python3.7/site-packages/appium/webdriver/webdriver.py", line 227, in start_session
    response = self.execute(RemoteCommand.NEW_SESSION, parameters)
  File "/Library/Frameworks/Python.framework/Versions/3.7/lib/python3.7/site-packages/selenium/webdriver/remote/webdriver.py", line 321, in execute
    self.error_handler.check_response(response)
  File "/Library/Frameworks/Python.framework/Versions/3.7/lib/python3.7/site-packages/selenium/webdriver/remote/errorhandler.py", line 242, in check_response
    raise exception_class(message, screen, stacktrace)
selenium.common.exceptions.WebDriverException: Message: An unknown server-side error occurred while processing the command. Original error: Unknown device or simulator UDID: '18b61a7bcd83c7d47a8e5a3d4c0202a6b2807c6f'


[2020-06-12 21:44:17,297][INFO] Appium iOS connects finished.
[2020-06-12 21:44:17,299][ERROR] Traceback (most recent call last):
  File "/Users/bindo1111/Documents/trash/qauto_sub_server/platforms/identifier.py", line 46, in connect
    cls.DRIVER = iOSAppium(cls.session)
  File "/Users/bindo1111/Documents/trash/qauto_sub_server/core/refactor/ios.py", line 34, in __init__
    super().__init__(session, platform="ios")
  File "/Users/bindo1111/Documents/trash/qauto_sub_server/core/refactor/appium_refactor.py", line 45, in __init__
    self.init_driver = webdriver.Remote("http://localhost:4723/wd/hub", session)
  File "/Library/Frameworks/Python.framework/Versions/3.7/lib/python3.7/site-packages/appium/webdriver/webdriver.py", line 151, in __init__
    proxy
  File "/Library/Frameworks/Python.framework/Versions/3.7/lib/python3.7/site-packages/selenium/webdriver/remote/webdriver.py", line 157, in __init__
    self.start_session(capabilities, browser_profile)
  File "/Library/Frameworks/Python.framework/Versions/3.7/lib/python3.7/site-packages/appium/webdriver/webdriver.py", line 227, in start_session
    response = self.execute(RemoteCommand.NEW_SESSION, parameters)
  File "/Library/Frameworks/Python.framework/Versions/3.7/lib/python3.7/site-packages/selenium/webdriver/remote/webdriver.py", line 321, in execute
    self.error_handler.check_response(response)
  File "/Library/Frameworks/Python.framework/Versions/3.7/lib/python3.7/site-packages/selenium/webdriver/remote/errorhandler.py", line 242, in check_response
    raise exception_class(message, screen, stacktrace)
selenium.common.exceptions.WebDriverException: Message: An unknown server-side error occurred while processing the command. Original error: Unknown device or simulator UDID: '18b61a7bcd83c7d47a8e5a3d4c0202a6b2807c6f'


[2020-06-12 21:44:17,301][INFO] Appium iOS connects finished.
[2020-06-12 21:44:17,335][INFO] ================== Finished in 0.3s. ==================
[2020-06-12 21:44:17,336][INFO] ================== Finished in 0.4s. ==================
