[2020-06-13 00:00:05,575][INFO] Appium iOS starts connecting.
[2020-06-13 00:00:05,576][INFO] Automated testing starts success.
[2020-06-13 00:00:05,800][ERROR] Traceback (most recent call last):
  File "/Users/bindo1111/Documents/trash/qauto_sub_server/platforms/identifier.py", line 46, in connect
    cls.DRIVER = iOSAppium(cls.session)
  File "/Users/bindo1111/Documents/trash/qauto_sub_server/core/refactor/ios.py", line 34, in __init__
    super().__init__(session, platform="ios")
  File "/Users/bindo1111/Documents/trash/qauto_sub_server/core/refactor/appium_refactor.py", line 45, in __init__
    self.init_driver = webdriver.Remote("http://localhost:4723/wd/hub", session)
  File "/Library/Frameworks/Python.framework/Versions/3.7/lib/python3.7/site-packages/appium/webdriver/webdriver.py", line 151, in __init__
    proxy
  File "/Library/Frameworks/Python.framework/Versions/3.7/lib/python3.7/site-packages/selenium/webdriver/remote/webdriver.py", line 157, in __init__
    self.start_session(capabilities, browser_profile)
  File "/Library/Frameworks/Python.framework/Versions/3.7/lib/python3.7/site-packages/appium/webdriver/webdriver.py", line 227, in start_session
    response = self.execute(RemoteCommand.NEW_SESSION, parameters)
  File "/Library/Frameworks/Python.framework/Versions/3.7/lib/python3.7/site-packages/selenium/webdriver/remote/webdriver.py", line 321, in execute
    self.error_handler.check_response(response)
  File "/Library/Frameworks/Python.framework/Versions/3.7/lib/python3.7/site-packages/selenium/webdriver/remote/errorhandler.py", line 242, in check_response
    raise exception_class(message, screen, stacktrace)
selenium.common.exceptions.WebDriverException: Message: An unknown server-side error occurred while processing the command. Original error: Unknown device or simulator UDID: '18b61a7bcd83c7d47a8e5a3d4c0202a6b2807c6f'


[2020-06-13 00:00:05,800][INFO] Appium iOS connects finished.
[2020-06-13 00:00:05,829][INFO] ================== Finished in 0.3s. ==================
